Workbook
Name FiltroDati_CATEGORIA: #REF!
Name FiltroDati_PRODOTTO: #REF!

Sheet CHIUSURA
A1: PRODOTTO | B1: COD. PROD. | C1: CATEGORIA | D1: QUANTITA' | E1: PREZZO UNITARIO | F1: TOTALE | G1: Prodotto_Report | H1: Categoria_Report | I1: TOT. IMP. | J1: PERCENTUALE | K1: COSTO UNITARIO | L1: COSTO TOTALE | M1: MARGINE | N1: % MARGINE
A2: COPERTO | B2: 51 | C2: --CLIENTE-- | D2: 30 | E2: =+Chiusura[[#This Row],[TOTALE]]/Chiusura[[#This Row],[QUANTITA'']] -> 1.489 | F2: 44.67 | G2: =IF(OR(A2="Coperto",A2="Servizio"),"",A2) | H2: =IF(OR(C2="--Cliente--",C2="Servizio"),"",C2) | I2: =IFERROR(F2/1.1,0) -> 40.609091 | J2: =I2/$I$74 -> 0.025767487 | K2: =IFERROR(INDEX('FOOD-DRINK COST'!E:E,MATCH('CHIUSURA'!B2,'FOOD-DRINK COST'!C:C,0)),0) -> 0 | L2: =Chiusura[[#This Row],[COSTO UNITARIO]]*D2 -> 0 | M2: =IF(K2=0,0,(I2-L2)) -> 0 | N2: =IFERROR(M2/I2,0) -> 0
A3: FISH | B3: 55 | C3: --CLIENTE-- | D3: 90 | E3: =+Chiusura[[#This Row],[TOTALE]]/Chiusura[[#This Row],[QUANTITA'']] -> 2.8888889 | F3: 260 | G3: =IF(OR(A3="Coperto",A3="Servizio"),"",A3) -> FISH | H3: =IF(OR(C3="Cliente",C3="Servizio"),"",C3) -> --CLIENTE-- | I3: =IFERROR(F3/1.1,0) -> 236.36364 | J3: =I3/$I$74 -> 0.14997866 | K3: =IFERROR(INDEX('FOOD-DRINK COST'!E:E,MATCH('CHIUSURA'!B3,'FOOD-DRINK COST'!C:C,0)),0) -> 0 | L3: =Chiusura[[#This Row],[COSTO UNITARIO]]*D3 -> 0 | M3: =IF(K3=0,0,(I3-L3)) -> 0 | N3: =IFERROR(M3/I3,0) -> 0
A4: CAPPUCCINO | B4: 115 | C4: --CAFFETTERIA-- | D4: 8 | E4: =+Chiusura[[#This Row],[TOTALE]]/Chiusura[[#This Row],[QUANTITA'']] -> 1.95 | F4: 15.6 | G4: =IF(OR(A4="Coperto",A4="Servizio"),"",A4) -> CAPPUCCINO | H4: =IF(OR(C4="Cliente",C4="Servizio"),"",C4) -> --CAFFETTERIA-- | I4: =IFERROR(F4/1.1,0) -> 14.181818 | J4: =I4/$I$74 -> 0.0089987194 | K4: =IFERROR(INDEX('FOOD-DRINK COST'!E:E,MATCH('CHIUSURA'!B4,'FOOD-DRINK COST'!C:C,0)),0) -> 0.3 | L4: =Chiusura[[#This Row],[COSTO UNITARIO]]*D4 -> 2.4 | M4: =IF(K4=0,0,(I4-L4)) -> 11.781818 | N4: =IFERROR(M4/I4,0) -> 0.83076923
A5: PASTA | B5: 131 | C5: --CAFFETTERIA-- | D5: 14 | E5: =+Chiusura[[#This Row],[TOTALE]]/Chiusura[[#This Row],[QUANTITA'']] -> 1.4464286 | F5: 20.25 | G5: =IF(OR(A5="Coperto",A5="Servizio"),"",A5) -> PASTA | H5: =IF(OR(C5="Cliente",C5="Servizio"),"",C5) -> --CAFFETTERIA-- | I5: =IFERROR(F5/1.1,0) -> 18.409091 | J5: =I5/$I$74 -> 0.01168103 | K5: =IFERROR(INDEX('FOOD-DRINK COST'!E:E,MATCH('CHIUSURA'!B5,'FOOD-DRINK COST'!C:C,0)),0) -> 0.7 | L5: =Chiusura[[#This Row],[COSTO UNITARIO]]*D5 -> 9.8 | M5: =IF(K5=0,0,(I5-L5)) -> 8.6090909 | N5: =IFERROR(M5/I5,0) -> 0.46765432
A6: CAFFE | B6: 101 | C6: --CAFFETTERIA-- | D6: 32 | E6: =+Chiusura[[#This Row],[TOTALE]]/Chiusura[[#This Row],[QUANTITA'']] -> 1.1996875 | F6: 38.39 | G6: =IF(OR(A6="Coperto",A6="Servizio"),"",A6) -> CAFFE | H6: =IF(OR(C6="Cliente",C6="Servizio"),"",C6) -> --CAFFETTERIA-- | I6: =IFERROR(F6/1.1,0) -> 34.9 | J6: =I6/$I$74 -> 0.022144926 | K6: =IFERROR(INDEX('FOOD-DRINK COST'!E:E,MATCH('CHIUSURA'!B6,'FOOD-DRINK COST'!C:C,0)),0) -> 0.2 | L6: =Chiusura[[#This Row],[COSTO UNITARIO]]*D6 -> 6.4 | M6: =IF(K6=0,0,(I6-L6)) -> 28.5 | N6: =IFERROR(M6/I6,0) -> 0.81661891
A7: CAFFE MACCHIATO CALDO | B7: 133 | C7: --CAFFETTERIA-- | D7: 4 | E7: =+Chiusura[[#This Row],[TOTALE]]/Chiusura[[#This Row],[QUANTITA'']] -> 1.4625 | F7: 5.85 | G7: =IF(OR(A7="Coperto",A7="Servizio"),"",A7) -> CAFFE MACCHIATO CALDO | H7: =IF(OR(C7="Cliente",C7="Servizio"),"",C7) -> --CAFFETTERIA-- | I7: =IFERROR(F7/1.1,0) -> 5.3181818 | J7: =I7/$I$74 -> 0.0033745198 | K7: =IFERROR(INDEX('FOOD-DRINK COST'!E:E,MATCH('CHIUSURA'!B7,'FOOD-DRINK COST'!C:C,0)),0) -> 0.22 | L7: =Chiusura[[#This Row],[COSTO UNITARIO]]*D7 -> 0.88 | M7: =IF(K7=0,0,(I7-L7)) -> 4.4381818 | N7: =IFERROR(M7/I7,0) -> 0.83452991
A8: GINSENG DOLCE | B8: 109 | C8: --CAFFETTERIA-- | D8: 5 | E8: =+Chiusura[[#This Row],[TOTALE]]/Chiusura[[#This Row],[QUANTITA'']] -> 1.438 | F8: 7.19 | G8: =IF(OR(A8="Coperto",A8="Servizio"),"",A8) -> GINSENG DOLCE | H8: =IF(OR(C8="Cliente",C8="Servizio"),"",C8) -> --CAFFETTERIA-- | I8: =IFERROR(F8/1.1,0) -> 6.5363636 | J8: =I8/$I$74 -> 0.0041474867 | K8: =IFERROR(INDEX('FOOD-DRINK COST'!E:E,MATCH('CHIUSURA'!B8,'FOOD-DRINK COST'!C:C,0)),0) -> 0.3 | L8: =Chiusura[[#This Row],[COSTO UNITARIO]]*D8 -> 1.5 | M8: =IF(K8=0,0,(I8-L8)) -> 5.0363636 | N8: =IFERROR(M8/I8,0) -> 0.7705146
A9: CAFFE E LATTE | B9: 120 | C9: --CAFFETTERIA-- | D9: 1 | E9: =+Chiusura[[#This Row],[TOTALE]]/Chiusura[[#This Row],[QUANTITA'']] -> 2 | F9: 2 | G9: =IF(OR(A9="Coperto",A9="Servizio"),"",A9) -> CAFFE E LATTE | H9: =IF(OR(C9="Cliente",C9="Servizio"),"",C9) -> --CAFFETTERIA-- | I9: =IFERROR(F9/1.1,0) -> 1.8181818 | J9: =I9/$I$74 -> 0.001153682 | K9: =IFERROR(INDEX('FOOD-DRINK COST'!E:E,MATCH('CHIUSURA'!B9,'FOOD-DRINK COST'!C:C,0)),0) -> 0.35 | L9: =Chiusura[[#This Row],[COSTO UNITARIO]]*D9 -> 0.35 | M9: =IF(K9=0,0,(I9-L9)) -> 1.4681818 | N9: =IFERROR(M9/I9,0) -> 0.8075
A10: GINSENG AMARO | B10: 147 | C10: --CAFFETTERIA-- | D10: 5 | E10: =+Chiusura[[#This Row],[TOTALE]]/Chiusura[[#This Row],[QUANTITA'']] -> 1.38 | F10: 6.9 | G10: =IF(OR(A10="Coperto",A10="Servizio"),"",A10) -> GINSENG AMARO | H10: =IF(OR(C10="Cliente",C10="Servizio"),"",C10) -> --CAFFETTERIA-- | I10: =IFERROR(F10/1.1,0) -> 6.2727273 | J10: =I10/$I$74 -> 0.0039802028 | K10: =IFERROR(INDEX('FOOD-DRINK COST'!E:E,MATCH('CHIUSURA'!B10,'FOOD-DRINK COST'!C:C,0)),0) -> 0.3 | L10: =Chiusura[[#This Row],[COSTO UNITARIO]]*D10 -> 1.5 | M10: =IF(K10=0,0,(I10-L10)) -> 4.7727273 | N10: =IFERROR(M10/I10,0) -> 0.76086957
A11: MIGNON | B11: 166 | C11: --CAFFETTERIA-- | D11: 3 | E11: =+Chiusura[[#This Row],[TOTALE]]/Chiusura[[#This Row],[QUANTITA'']] -> 0.88666667 | F11: 2.66 | G11: =IF(OR(A11="Coperto",A11="Servizio"),"",A11) -> MIGNON | H11: =IF(OR(C11="Cliente",C11="Servizio"),"",C11) -> --CAFFETTERIA-- | I11: =IFERROR(F11/1.1,0) -> 2.4181818 | J11: =I11/$I$74 -> 0.001534397 | K11: =IFERROR(INDEX('FOOD-DRINK COST'!E:E,MATCH('CHIUSURA'!B11,'FOOD-DRINK COST'!C:C,0)),0) -> 0.38222222 | L11: =Chiusura[[#This Row],[COSTO UNITARIO]]*D11 -> 1.1466667 | M11: =IF(K11=0,0,(I11-L11)) -> 1.2715152 | N11: =IFERROR(M11/I11,0) -> 0.52581454
A12: BISCOTTO FARCITO | B12: 177 | C12: --CAFFETTERIA-- | D12: 2 | E12: =+Chiusura[[#This Row],[TOTALE]]/Chiusura[[#This Row],[QUANTITA'']] -> 0.895 | F12: 1.79 | G12: =IF(OR(A12="Coperto",A12="Servizio"),"",A12) -> BISCOTTO FARCITO | H12: =IF(OR(C12="Cliente",C12="Servizio"),"",C12) -> --CAFFETTERIA-- | I12: =IFERROR(F12/1.1,0) -> 1.6272727 | J12: =I12/$I$74 -> 0.0010325454 | K12: =IFERROR(INDEX('FOOD-DRINK COST'!E:E,MATCH('CHIUSURA'!B12,'FOOD-DRINK COST'!C:C,0)),0) -> 0.38222222 | L12: =Chiusura[[#This Row],[COSTO UNITARIO]]*D12 -> 0.76444444 | M12: =IF(K12=0,0,(I12-L12)) -> 0.86282828 | N12: =IFERROR(M12/I12,0) -> 0.53022967
A13: CAFFE CORRETTO | B13: 102 | C13: --CAFFETTERIA-- | D13: 1 | E13: =+Chiusura[[#This Row],[TOTALE]]/Chiusura[[#This Row],[QUANTITA'']] -> 2.5 | F13: 2.5 | G13: =IF(OR(A13="Coperto",A13="Servizio"),"",A13) -> CAFFE CORRETTO | H13: =IF(OR(C13="Cliente",C13="Servizio"),"",C13) -> --CAFFETTERIA-- | I13: =IFERROR(F13/1.1,0) -> 2.2727273 | J13: =I13/$I$74 -> 0.0014421025 | K13: =IFERROR(INDEX('FOOD-DRINK COST'!E:E,MATCH('CHIUSURA'!B13,'FOOD-DRINK COST'!C:C,0)),0) -> 0.25 | L13: =Chiusura[[#This Row],[COSTO UNITARIO]]*D13 -> 0.25 | M13: =IF(K13=0,0,(I13-L13)) -> 2.0227273 | N13: =IFERROR(M13/I13,0) -> 0.89
A14: ACQUA BICC GAS | B14: 201 | C14: --BIBITE-- | D14: 4 | E14: =+Chiusura[[#This Row],[TOTALE]]/Chiusura[[#This Row],[QUANTITA'']] -> 0.2925 | F14: 1.17 | G14: =IF(OR(A14="Coperto",A14="Servizio"),"",A14) -> ACQUA BICC GAS | H14: =IF(OR(C14="Cliente",C14="Servizio"),"",C14) -> --BIBITE-- | I14: =IFERROR(F14/1.1,0) -> 1.0636364 | J14: =I14/$I$74 -> 0.00067490396 | K14: =IFERROR(INDEX('FOOD-DRINK COST'!E:E,MATCH('CHIUSURA'!B14,'FOOD-DRINK COST'!C:C,0)),0) -> 0.13661042 | L14: =Chiusura[[#This Row],[COSTO UNITARIO]]*D14 -> 0.54644167 | M14: =IF(K14=0,0,(I14-L14)) -> 0.5171947 | N14: =IFERROR(M14/I14,0) -> 0.48625142
... A72: RUSTICA | B72: 4208 | C72: --PIZZE CREATIVE-- | D72: 2 | E72: =+Chiusura[[#This Row],[TOTALE]]/Chiusura[[#This Row],[QUANTITA'']] -> 13 | F72: 26 | G72: =IF(OR(A72="Coperto",A72="Servizio"),"",A72) -> RUSTICA | H72: =IF(OR(C72="Cliente",C72="Servizio"),"",C72) -> --PIZZE CREATIVE-- | I72: =IFERROR(F72/1.1,0) -> 23.636364 | J72: =I72/$I$74 -> 0.014997866 | K72: =IFERROR(INDEX('FOOD-DRINK COST'!E:E,MATCH('CHIUSURA'!B72,'FOOD-DRINK COST'!C:C,0)),0) -> 2.95 | L72: =Chiusura[[#This Row],[COSTO UNITARIO]]*D72 -> 5.9 | M72: =IF(K72=0,0,(I72-L72)) -> 17.736364 | N72: =IFERROR(M72/I72,0) -> 0.75038462
A73: SERVIZIO | B73: SERVIZIO | C73: SERVIZIO | D73: 63 | E73: =+Chiusura[[#This Row],[TOTALE]]/Chiusura[[#This Row],[QUANTITA'']] -> 0 | F73: 0 | G73: =IF(OR(A73="Coperto",A73="Servizio"),"",A73) | H73: =IF(OR(C73="Cliente",C73="Servizio"),"",C73) | I73: =IFERROR(F73/1.1,0) -> 0 | J73: =I73/$I$74 -> 0 | K73: =IFERROR(INDEX('FOOD-DRINK COST'!E:E,MATCH('CHIUSURA'!B73,'FOOD-DRINK COST'!C:C,0)),0) -> 0 | L73: =Chiusura[[#This Row],[COSTO UNITARIO]]*D73 -> 0 | M73: =IF(K73=0,0,(I73-L73)) -> 0 | N73: =IFERROR(M73/I73,0) -> 0
F74: =SUM(Chiusura[TOTALE]) -> 1733.58 | G74: =SUM(Chiusura[Prodotto_Report]) -> 0 | H74: =SUM(Chiusura[Categoria_Report]) -> 0 | I74: =SUM(Chiusura[TOT. IMP.]) -> 1575.9818 | L74: =SUM(Chiusura[COSTO TOTALE]) -> 406.09405 | M74: =SUM(Chiusura[MARGINE]) -> 774.38777 | N74: =AVERAGE(Chiusura[% MARGINE]) -> 0.60298174

Sheet Pivot_Antipasti_Qta
A1: CATEGORIA | B1: --ANTIPASTI--
A3: Etichette di riga | B3: Somma di QUANTITA'
A4: ANTIPASTO DEL GIORNO | B4: 2
A5: POLPETTE ALLA CARBONARA | B5: 2
A6: MENU GASTRONOMIA | B6: 9
A7: Totale complessivo | B7: 13

Sheet Pivot_Dolci_Qta
A1: CATEGORIA | B1: --DOLCI--
A3: Etichette di riga | B3: Somma di QUANTITA'
A4: TIRAMISU | B4: 6
A5: GELATO PRINCIPESSA | B5: 1
A6: Totale complessivo | B6: 7

Sheet Pivot_Cat_€
A1: CATEGORIA | B1: (più elementi)
A3: Etichette di riga | B3: Somma di TOT. IMP.
A4: --ANTIPASTI-- | B4: 245.77273
A5: --APERITIVI-- | B5: 108.45455
A6: --BIRRE-- | B6: 108.12727
A7: --CAFFETTERIA-- | B7: 93.754545
A8: --SECONDI-- | B8: 161.11818
A9: Totale complessivo | B9: 717.22727

Sheet Pivot_Prod_€
A1: PRODOTTO | B1: (più elementi)
A2: CATEGORIA | B2: (più elementi)
A4: Etichette di riga | B4: Somma di TOT. IMP.
A5: GIN MARE | B5: 65.454545
A6: SHOT | B6: 4.5454545
A7: Totale complessivo | B7: 70

Sheet Pivot_Primi_Qta
A1: PRODOTTO | B1: (più elementi)
A2: CATEGORIA | B2: --PRIMI--
A4: Etichette di riga | B4: Somma di QUANTITA'
A5: REGINETTE IMPERIALI | B5: 1
A6: RIGATONI ALLA CARBONARA | B6: 1
A7: Totale complessivo | B7: 2

Sheet Pivot_Secondi_Qta 
A1: PRODOTTO | B1: (più elementi)
A2: CATEGORIA | B2: --SECONDI--
A4: Etichette di riga | B4: Somma di QUANTITA'
A5: COSTATA DI SCOTTONA | B5: 2
A6: COTOLETTA DI MAIALE | B6: 1
A7: SECONDO DEL GIORNO | B7: 3
A8: TAGLIATA DI MANZO | B8: 1
A9: Totale complessivo | B9: 7

Sheet Pivot_Pizze_Qta
A1: PRODOTTO | B1: (più elementi)
A2: CATEGORIA | B2: (più elementi)
A4: Etichette di riga | B4: Somma di QUANTITA'
A5: MARGHERITA | B5: 2
A6: NAPOLI | B6: 1
A7: ORTOLANA | B7: 1
A8: RUSTICA | B8: 2
A9: Totale complessivo | B9: 6

Sheet Pivot_Hamburger_Qta
A1: PRODOTTO | B1: (più elementi)
A2: CATEGORIA | B2: --BURGER MENU--
A4: Etichette di riga | B4: Somma di QUANTITA'
A5: BREAD AND PORK | B5: 2
A6: Totale complessivo | B6: 2

Sheet Margine_Cat.
A1: CATEGORIA | B1: (più elementi)
A3: Etichette di riga | B3: Media di % MARGINE
A4: --AMARI E LIQUORI-- | B4: 0.78771133
A5: --APERITIVI-- | B5: 0.75275099
A6: --BABY-- | B6: 0.66666667
A7: --BIBITE-- | B7: 0.72789604
A8: --BURGER MENU-- | B8: 0.66666667
A9: --CAFFETTERIA-- | B9: 0.72345008
A10: --COCKTAIL-- | B10: 0.824
A11: --CONTORNI-- | B11: 0.66666667
A12: --GIN-- | B12: 0.72958333
A13: --INSALATE-- | B13: 0.66666667
A14: --PIZZE CLASSICHE-- | B14: 0.74365229
A15: --PIZZE CREATIVE-- | B15: 0.75038462
A16: Totale complessivo | B16: 0.73299185

Sheet Pivot_Caffetteria_Qta
A1: CATEGORIA | B1: --CAFFETTERIA--
A3: Etichette di riga | B3: Somma di QUANTITA'
A4: CAFFE | B4: 32
A5: CAPPUCCINO | B5: 8
A6: GINSENG AMARO | B6: 5
A7: GINSENG DOLCE | B7: 5
A8: PASTA | B8: 14
A9: Totale complessivo | B9: 64

Sheet Pivot_Vini_Bianchi_Qta
A1: CATEGORIA | B1: --VINI BIANCHI--
A3: Etichette di riga | B3: Somma di QUANTITA'
A4: CALA REALE BOTTIGLIA | B4: 1
A5: CALICE VINO BIANCO | B5: 4
A6: CALICE BLU | B6: 4
A7: CALICE GEWURZTRAMINER | B7: 2
A8: Totale complessivo | B8: 11

Sheet Pivot_Spumanti_Prosecco_Qta
A1: CATEGORIA | B1: (più elementi)
A3: Etichette di riga | B3: Somma di QUANTITA'
A4: Totale complessivo

Sheet MARGINE_DRINK
A1: CATEGORIA | B1: (più elementi)
A3: Etichette di riga | B3: Somma di % MARGINE
A4: CAMPARI SODA | B4: 0.70142857
A5: COCKTAIL SANPELLEGRINO | B5: 0.7853254
A6: GIN MARE | B6: 0.72958333
A7: NEGRONI | B7: 0.773125
A8: SHOT | B8: 0.824
A9: SPRITZ APEROL | B9: 0.751125
A10: Totale complessivo | B10: 4.5645873

Sheet MARGINE_PRIMI
A1: CATEGORIA | B1: --PRIMI--
A3: Etichette di riga | B3: Somma di % MARGINE
A4: REGINETTE IMPERIALI | B4: 0.66666667
A5: RIGATONI ALLA CARBONARA | B5: 0.64444444
A6: PRIMO DEL GIORNO CON ACQUA | B6: 0.23513514
A7: Totale complessivo | B7: 1.5462462

Sheet MARGINE_SECONDI
A1: CATEGORIA | B1: --SECONDI--
A3: Etichette di riga | B3: Somma di % MARGINE
A4: COSTATA DI SCOTTONA | B4: 0.35192308
A5: COTOLETTA DI MAIALE | B5: 0.62845011
A6: SECONDO DEL GIORNO | B6: 0
A7: TAGLIATA DI MANZO | B7: 0.66666667
A8: SECONDO DEL GIORNO CON ACQUA | B8: 0.18189256
A9: Totale complessivo | B9: 1.8289324

Sheet MARGINE_PIZZE
A1: CATEGORIA | B1: (più elementi)
A3: Etichette di riga | B3: Somma di % MARGINE
A4: MARGHERITA | B4: 0.79852632
A5: NAPOLI | B5: 0.709875
A6: ORTOLANA | B6: 0.72255556
A7: RUSTICA | B7: 0.75038462
A8: Totale complessivo | B8: 2.9813415

Sheet MARGINE_HAMBURGER
A1: CATEGORIA | B1: --BURGER MENU--
A3: Etichette di riga | B3: Somma di % MARGINE
A4: BREAD AND PORK | B4: 0.66666667
A5: HAMBURGER PANINO | B5: 0.66666667
A6: Totale complessivo | B6: 1.3333333

Sheet MARGINE_ANTIPASTI
A1: CATEGORIA | B1: --ANTIPASTI--
A3: Etichette di riga | B3: Somma di % MARGINE
A4: ANTIPASTO DEL GIORNO | B4: 0.534
A5: POLPETTE ALLA CARBONARA | B5: 0.75
A6: MENU GASTRONOMIA | B6: 0.60636183
A7: Totale complessivo | B7: 1.8903618

Sheet MARGINE_DOLCI
A1: CATEGORIA | B1: --DOLCI--
A3: Etichette di riga | B3: Somma di % MARGINE
A4: TIRAMISU | B4: 0
A5: GELATO PRINCIPESSA | B5: 0
A6: Totale complessivo | B6: 0

Sheet MARGINE_CAFFETTERIA
A1: CATEGORIA | B1: --CAFFETTERIA--
A3: Etichette di riga | B3: Somma di % MARGINE
A4: CAFFE | B4: 0.81661891
A5: CAFFE CORRETTO | B5: 0.89
A6: CAFFE E LATTE | B6: 0.8075
A7: CAFFE MACCHIATO CALDO | B7: 0.83452991
A8: CAPPUCCINO | B8: 0.83076923
A9: GINSENG AMARO | B9: 0.76086957
A10: GINSENG DOLCE | B10: 0.7705146
A11: MIGNON | B11: 0.52581454
A12: PASTA | B12: 0.46765432
A13: BISCOTTO FARCITO | B13: 0.53022967
A14: Totale complessivo | B14: 7.2345008

Sheet MARGINE_VINI_BIANCHI
A1: CATEGORIA | B1: --VINI BIANCHI--
A3: Etichette di riga | B3: Somma di % MARGINE
A4: CALA REALE BOTTIGLIA | B4: 0.61683333
A5: CALICE VINO BIANCO | B5: 0.7558
A6: CALICE BLU | B6: 0
A7: CALICE GEWURZTRAMINER | B7: 0
A8: Totale complessivo | B8: 1.3726333

Sheet MARGINE_VINI_ROSSI_ROSATI
A1: CATEGORIA | B1: --VINI ROSSI E ROSATI--
A3: Etichette di riga | B3: Somma di % MARGINE
A4: CALICE BOVALE | B4: 0.83282439
A5: CALICE KRESSIA | B5: 0.71928
A6: CALICE VINO ROSSO | B6: 0.736
A7: CALICE AKENTA ROSE | B7: 0
A8: Totale complessivo | B8: 2.2881044

Sheet MARGINE_SPUMANTI_PROSECCO
A1: CATEGORIA | B1: (più elementi)
A3: Etichette di riga | B3: Somma di % MARGINE
A4: Totale complessivo

Sheet PIVOT CAT QTA
A1: CATEGORIA | B1: (più elementi)
A3: Etichette di riga | B3: Somma di QUANTITA'
A4: --AMARI E LIQUORI-- | B4: 22
A5: --APERITIVI-- | B5: 24
A6: --BIBITE-- | B6: 33
A7: --BIRRE-- | B7: 29
A8: --CAFFETTERIA-- | B8: 75
A9: Totale complessivo | B9: 183

Sheet BIRRA
A1: CATEGORIA | B1: --BIRRE--
A3: Etichette di riga | B3: Somma di QUANTITA'
A4: CARAFFA HEINEKEN 1L | B4: 2
A5: HEINEKEN ANALCOLICA | B5: 1
A6: SPINA BLANCHE 0,33 | B6: 2
A7: SPINA HEINEKEN 0,25 | B7: 23
A8: SPINA HEINEKEN 0,50 | B8: 1
A9: Totale complessivo | B9: 29

Sheet BIRRA_MARGINE
A1: CATEGORIA | B1: --BIRRE--
A3: Etichette di riga | B3: Media di % MARGINE
A4: CARAFFA HEINEKEN 1L | B4: 0.67916667
A5: HEINEKEN ANALCOLICA | B5: 0.73359375
A6: SPINA BLANCHE 0,33 | B6: 0.425855
A7: SPINA HEINEKEN 0,25 | B7: 0.71413352
A8: SPINA HEINEKEN 0,50 | B8: 0.65
A9: Totale complessivo | B9: 0.64054979

Sheet FOOD-DRINK COST
A1: Colonna1 | B1: DESCRIZIONE | C1: CODICE PRODOTTO | D1: COSTO TOT. | E1: COSTO UNIT. | F1: Colonna2
A2: --CLIENTE-- | B2: COPERTO | C2: 51
A3: --CAFFETTERIA-- | B3: CAFFE | C3: 101 | E3: 0.2
A4: --CAFFETTERIA-- | B4: CAFFE CORRETTO | C4: 102 | E4: 0.25
A5: --CAFFETTERIA-- | B5: MAROCCHINO | C5: 104 | E5: 0.28
A6: --CAFFETTERIA-- | B6: GINSENG DOLCE | C6: 109 | E6: 0.3
A7: --CAFFETTERIA-- | B7: GINSENG DOLCE GRANDE | C7: 110 | E7: 0.35
A8: --CAFFETTERIA-- | B8: CAFFE DEK | C8: 111 | E8: 0.36
A9: --CAFFETTERIA-- | B9: CAFFE DOPPIO | C9: 113 | E9: 0.2
A10: --CAFFETTERIA-- | B10: CAPPUCCINO | C10: 115 | E10: 0.3
A11: --CAFFETTERIA-- | B11: CAPPUCCINO DEK | C11: 116 | E11: 0.46
A12: --CAFFETTERIA-- | B12: CAPPUCCINO GINSENG | C12: 118 | E12: 0.4
A13: --CAFFETTERIA-- | B13: CAFFE E LATTE | C13: 120 | E13: 0.35
A14: --CAFFETTERIA-- | B14: LATTE MACCHIATO | C14: 124 | E14: 0.38
A15: --CAFFETTERIA-- | B15: LATTE BIANCO | C15: 125 | D15: 1.53 | E15: =+(Tabella2[[#This Row],[COSTO TOT.]]/100)*25 -> 0.3825
A16: --CAFFETTERIA-- | B16: THE CALDO | C16: 126 | E16: 0.1
A17: --CAFFETTERIA-- | B17: TISANA | C17: 128 | E17: 0.1
A18: --CAFFETTERIA-- | B18: CIOCCOLATA | C18: 129 | D18: 109 | E18: =+Tabella2[[#This Row],[COSTO TOT.]]/96 -> 1.1354167
A19: --CAFFETTERIA-- | B19: choko | C19: 130 | E19: 0.34
A20: --CAFFETTERIA-- | B20: CIOCCOLATA CON PANNA | C20: 130 | E20: 0.9
A21: --CAFFETTERIA-- | B21: PASTA | C21: 131 | E21: 0.7
A22: --CAFFETTERIA-- | B22: CAFFE MACCHIATO FREDDO | C22: 132 | E22: 0.22
A23: --CAFFETTERIA-- | B23: CAFFE MACCHIATO CALDO | C23: 133 | E23: 0.22
A24: --CAFFETTERIA-- | B24: CAPPUCCINO SOIA | C24: 134 | E24: 0.4
A25: --CAFFETTERIA-- | B25: CREMA CAFFE | C25: 136 | E25: 0.95
A26: --CAFFETTERIA-- | B26: GINSENG AMARO | C26: 147 | E26: 0.3
A27: --CAFFETTERIA-- | B27: GINSENG AMARO GRANDE | C27: 148 | E27: 0.35
A28: --CAFFETTERIA-- | B28: CAFFE RISTRETTO | C28: 149 | E28: 0.2
A29: --CAFFETTERIA-- | B29: CAFFE LUNGO | C29: 150 | E29: 0.2
A30: --CAFFETTERIA-- | B30: SCHIUMETTA DI LATTE | C30: 151 | E30: 0.1
... A35: --CAFFETTERIA-- | B35: EGOCCINO | C35: 162 | E35: 1.1
A36: --CAFFETTERIA-- | B36: MIGNON | C36: 166 | D36: 34.4 | E36: =+Tabella2[[#This Row],[COSTO TOT.]]/90 -> 0.38222222
A37: --CAFFETTERIA-- | B37: MUFFIN | C37: 167 | D37: 42.05 | E37: =+Tabella2[[#This Row],[COSTO TOT.]]/30 -> 1.4016667
A38: --CAFFETTERIA-- | B38: DONUT | C38: 168 | D38: 37.98 | E38: =+Tabella2[[#This Row],[COSTO TOT.]]/36 -> 1.055
A39: --CAFFETTERIA-- | B39: GINSENG MACCHIATO | C39: 169 | E39: 0.32
A40: --CAFFETTERIA-- | B40: CIOCCOLATA BIANCA | C40: 170 | D40: 109 | E40: =+Tabella2[[#This Row],[COSTO TOT.]]/96 -> 1.1354167
A41: --CAFFETTERIA-- | B41: CIOCCOLATA GIANDUIA | C41: 173 | D41: 109 | E41: =+Tabella2[[#This Row],[COSTO TOT.]]/96 -> 1.1354167
A42: --CAFFETTERIA-- | B42: BISCOTTO MIGNON | C42: 177 | D42: 34.4 | E42: =+Tabella2[[#This Row],[COSTO TOT.]]/90 -> 0.38222222
A43: --CAFFETTERIA-- | B43: FROLLINO | C43: 178 | E43: 0.38
A44: --BIBITE-- | B44: ACQUA BICC GAS | C44: 201 | D44: 6.5573 | E44: =+((Tabella2[[#This Row],[COSTO TOT.]]/12)/1)*0.25 -> 0.13661042
...

Sheet COSTI
A2: Affitto | B2: 7.000,00 € | C2: 233,33 €
A3: Personale ? | B3: 38000 | C3: =+B3/31 -> 1225.8065
A4: union gas | B4: 3300 | C4: =+B4/30 -> 110
A5: COSTI AL GG | C5: =+C4+C3+C2+E18 -> 1662.3322
A9: Categoria | B9: Fatturati | C9: Previsti | D9: Aliquota % | E9: Ammortamento Giorno
A10: =HYPERLINK("#A20","Cucina e Laboratorio") -> Cucina e Laboratorio | B10: =+SUM(cucina_lab[FATTURATI]) -> 19057.75 | C10: =SUM(cucina_lab[PREVISTI]) -> 62931.5 | D10: 0.12 | E10: =((Riepilogo[[#This Row],[Previsti]]+Riepilogo[[#This Row],[Fatturati]])*Riepilogo[[#This Row],[Aliquota %]])/365 -> 26.95537
A11: =HYPERLINK("#A58","Arredamento/Mobili/costr. legg.") -> Arredamento/Mobili/costr. legg. | B11: =+SUM(arred_mob[FATTURATI]) -> 60331.38 | C11: =SUM(arred_mob[PREVISTI]) -> 15898.8 | D11: 0.1 | E11: =((Riepilogo[[#This Row],[Previsti]]+Riepilogo[[#This Row],[Fatturati]])*Riepilogo[[#This Row],[Aliquota %]])/365 -> 20.884981
A12: =HYPERLINK("#A109","Tecnologia e Cassa") -> Tecnologia e Cassa | B12: =+SUM(tecn_cassa[FATTURATI]) -> 2955.482 | C12: =SUM(tecn_cassa[PREVISTI]) -> 0 | D12: 0.2 | E12: =((Riepilogo[[#This Row],[Previsti]]+Riepilogo[[#This Row],[Fatturati]])*Riepilogo[[#This Row],[Aliquota %]])/365 -> 1.6194422
A13: =HYPERLINK("#A119","Impianti e Audio") -> Impianti e Audio | B13: =+SUM(imp_audio[FATTURATI]) -> 8868.85 | C13: =SUM(imp_audio[PREVISTI]) -> 2500 | D13: 0.15 | E13: =((Riepilogo[[#This Row],[Previsti]]+Riepilogo[[#This Row],[Fatturati]])*Riepilogo[[#This Row],[Aliquota %]])/365 -> 4.6721301
A14: =HYPERLINK("#A124","Software di gestione") -> Software di gestione | B14: =+SUM(soft_gest[FATTURATI]) -> 3617.27 | C14: =SUM(soft_gest[PREVISTI]) -> 0 | D14: 0.3333 | E14: =((Riepilogo[[#This Row],[Previsti]]+Riepilogo[[#This Row],[Fatturati]])*Riepilogo[[#This Row],[Aliquota %]])/365 -> 3.3031126
A15: =HYPERLINK("#A137","Beni basso costo (<€516)") -> Beni basso costo (<€516) | B15: =+SUM(att_cuc[Fatturati]) -> 3279.052 | C15: =SUM(att_cuc[Previsti]) -> 0 | D15: 0.25 | E15: =((Riepilogo[[#This Row],[Previsti]]+Riepilogo[[#This Row],[Fatturati]])*Riepilogo[[#This Row],[Aliquota %]])/365 -> 2.245926
A16: =HYPERLINK("#A184","Attrezzatura (stoviglie, att. Cucina etc.)") -> Attrezzatura (stoviglie, att. Cucina etc.) | B16: =+SUM(beni_basso_costo[FATTURATI]) -> 2056.1213 | C16: =SUM(beni_basso_costo[PREVISTI]) -> 0 | D16: 1 | E16: =((Riepilogo[[#This Row],[Previsti]]+Riepilogo[[#This Row],[Fatturati]])*Riepilogo[[#This Row],[Aliquota %]])/365 -> 5.633209
A17: =HYPERLINK("#A303","Prestazioni di terzi") -> Prestazioni di terzi | B17: =+SUM(prest_terzi[Fatturati]) -> 10176.77 | C17: =SUM(prest_terzi[Previsti]) -> 0 | D17: 1 | E17: =((Riepilogo[[#This Row],[Previsti]]+Riepilogo[[#This Row],[Fatturati]])*Riepilogo[[#This Row],[Aliquota %]])/365 -> 27.881562
A18: TOTALE | B18: =SUM(B10:B17) -> 110342.68 | C18: =SUM(C10:C17) -> 81330.3 | E18: =SUM(E10:E17) -> 93.195732
E19: =((Riepilogo[[#This Row],[Previsti]]+Riepilogo[[#This Row],[Fatturati]])*Riepilogo[[#This Row],[Aliquota %]])/365 -> 0
A20: Cucina e Laboratorio | B20: FATTURATI | C20: PREVISTI | D20: =HYPERLINK("#A7","Riepilogo") -> Riepilogo
A21: Forno pizza | B21: 13000
A22: Cappa parete inox 3000 | C22: 1325
A23: Cappa parete inox 1500 | C23: 1091.3
A24: Lampade incasso cappa | C24: 575
A25: Quadro elettrico inverter | C25: 1290
A26: Centraline CDAS 40 | C26: 3525
A27: Cuocipasta elettrico 26 lt | C27: 1883
A28: Cestello cuocipasta | C28: 133
A29: Testata inox | C29: 29
A30: Affettatrice Sirmann CNV 300 | C30: 795
A31: Induzione 2 zone | C31: 497.5
A32: Induzione 2 zone (2) | C32: 696.5
A33: Fry-top piastra mista | C33: 4454.1
... A49: Trasporto e installazione | C49: 1950
A50: F. MICRO 1000W 25L GMW1125 MP | B50: 239
A51: "BANCO BAR REFRIGERATO CON BANCALINA | C51: 6430
A52: "BANCO DOCK P600 FREDDO VENTILATO | C52: 2125
A53: "Supplemento per unit¨¤ refrigerante esterna 20 | C53: 297.5
A54: LAVAST. STEELTECH 45-00D 230/50-1N | B54: 2030
A55: PIZZERIA IMPASTATRICE A SPIRALE CONTI | B55: 3678.75
A56: PIZZERIA MISCELATORE MONOFORO CON LEVA CLINICA | B56: 110
A58: Arredamento/Mobili/costr. legg. | B58: FATTURATI | C58: PREVISTI | D58: =HYPERLINK("#A7","Riepilogo") -> Riepilogo
A59: Tavolo inox | C59: 255
A60: Tavolo su gambe | C60: 320.6
...
